Workbook

Sheet Portada
B2: DECLARACIÓN DE APLICABILIDAD (SoA) – ESQUEMA NACIONAL DE SEGURIDAD
B3: Real Decreto 311/2022, de 3 de mayo – Anexo II · Categoría del sistema: ALTA
B4: Documento de ejemplo con datos ficticios para uso docente (caso TechServ).
B6: Organización | C6: TechServ Administración, S.L. – B-87.654.321 (ficticio)
B7: Sistema de información | C7: PSTA – Plataforma de Servicios TIC para la Administración Autonómica
B8: Código / versión del documento | C8: SOA-ENS-PSTA · v2.0
B9: Fecha de emisión | C9: 18/09/2026
B10: Categoría del sistema (art. 40, Anexo I) | C10: ALTA (D=ALTO · I=ALTO · C=ALTO · A=ALTO · T=MEDIO) – ver hoja 'Categorización'
B11: Análisis de riesgos de referencia (art. 14, [op.pl.1]) | C11: AR-2026-01 (MAGERIT v3 / PILAR), aprobado por el CSI el 30/06/2026
B12: Elaborada por | C12: Laura Ortega Vidal – Responsable de Seguridad (CISO)
B13: Revisada por | C13: Javier Molina Ruiz – Responsable del Sistema (CTO)
B14: Aprobada por | C14: Comité de Seguridad de la Información (CSI) – reunión trimestral – acta ACTA-CSI-2026-03
B15: Responsables de la Información / del Servicio | C15: Consejería de Hacienda / Consejería de Educación / Consejería de Bienestar Social (Responsables de la Información y del Servicio, art. 11 RD 311/2022)
B16: Delegada de Protección de Datos | C16: Marta Ruiz Salgado – Delegada de Protección de Datos
B17: Firma (art. 28.2 RD 311/2022) | C17: Firmado electrónicamente por la Responsable de Seguridad con certificado cualificado – 18/09/2026
... B19: Infraestructura | C19: CPD principal – Alcobendas (Madrid) CPD de respaldo – Tres Cantos (Madrid), distancia 14 km IaaS/PaaS en proveedor con certificación ENS categoría ALTA (NubeAdmin Cloud, S.A.) para el portal público y copias externas SOC 24x7 subcontratado a SecOps Iberia, S.L. (certificado ENS ALTA, ISO 27001) integrado con el CCN-CERT vía LUCIA/REYES
B21: Contenido del libro
B22: Ámbito y perfil | C22: Ámbito de aplicación (art. 2.3), aplicación total/parcial, perfil de cumplimiento específico (art. 30), criterios de selección (art. 28) y regla de aplicación por dimensión.
B23: Categorización | C23: Valoración de los activos esenciales en las cinco dimensiones (Anexo I) y determinación del nivel por dimensión y de la categoría del sistema.
B24: SoA ENS | C24: Las 73 medidas del Anexo II: dimensiones, exigencia BAJO/MEDIO/ALTO, nivel exigido a TechServ, refuerzos, aplicabilidad y justificación, medidas organizativas y técnicas, evidencias, responsable, estado y equivalencia ISO/IEC 27001:2022 (CCN-STIC 825).
B25: Refuerzos | C25: Detalle de cada requisito de refuerzo Rn: nivel en que se exige, si es exigible a TechServ, alternativa elegida e implementación.
B26: Medidas compensatorias | C26: Registro de medidas compensatorias (art. 28.3) con ámbito, limitación, riesgo, medida, validación y mantenimiento.
B27: Resumen | C27: Indicadores calculados con fórmulas: medidas aplicables, no aplicables, compensadas, estado de implantación y grado de cumplimiento por marco.
B28: Texto Anexo II | C28: Texto normativo de cada medida y de sus refuerzos (RD 311/2022) para consulta.
B29: Leyenda | C29: Códigos de colores, valores permitidos y celdas editables.
B31: Control de cambios
B32: Versión / fecha | C32: Descripción
B33: v1.0 – 15/02/2025 | C33: Primera emisión tras la categorización inicial (categoría MEDIA, T=MEDIO, C=MEDIO).
B34: v1.1 – 10/10/2025 | C34: Actualización tras auditoría de certificación: refuerzos op.acc.6 R6/R7 y op.exp.8 R3.
B35: v2.0 – 18/09/2026 | C35: Re-categorización a ALTA por incorporación de S-03 (datos de salud) y valoración D=ALTO de S-01; nuevo análisis de riesgos AR-2026-01; medidas compensatorias MC-01..04; mapeo ISO 27001:2022.

Sheet Ámbito y perfil
A1: Aspecto | B1: Determinación para TechServ / PSTA
A2: Naturaleza de la entidad | B2: Entidad del sector privado (S.L., 85 empleados) que presta servicios TIC a tres consejerías de una Comunidad Autónoma en virtud de contrato administrativo.
A3: Base jurídica de aplicación del ENS | B3: Art. 2.3 RD 311/2022: el ENS se aplica a los sistemas de información de entidades del sector privado cuando, en virtud de una relación contractual, presten servicios o provean soluciones al sector público para el ejercicio de sus competencias. Los pliegos (PPT cláusula 14) exigen conformidad ENS categoría ALTA con certificación en vigor.
A4: Modalidad de aplicación: TOTAL vs PARCIAL | B4: APLICACIÓN PARCIAL (por alcance): el ENS se aplica a los sistemas que soportan los servicios prestados a las consejerías (sistema PSTA: CPD Alcobendas, CPD Tres Cantos, tenant IaaS NubeAdmin, puestos de administración y operación). NO se incluyen en el alcance ENS los sistemas corporativos internos de TechServ sin relación con el servicio (ERP/facturación, RRHH, web comercial), que se gobiernan bajo el SGSI ISO 27001 de la compañía. La frontera está documentada en DOC-ALC-01 (alcance) y en el diagrama de arquitectura ARQ-02.
A5: Perfil de cumplimiento específico (art. 30 RD 311/2022) | B5: NO APLICA ningún perfil de cumplimiento específico. Los perfiles publicados por el CCN (serie CCN-STIC 88x/89x: p. ej. 881A Universidades, 884 Cloud corporativo Azure, 890A Requisitos esenciales para categoría BÁSICA, 890C) están concebidos para entidades o sectores concretos y/o categorías inferiores. TechServ, como prestador privado de un sistema de categoría ALTA con dimensiones ALTO en D/I/C/A, debe aplicar el Anexo II completo con los refuerzos exigidos para su nivel. Se deja constancia de que, si la Consejería contratante dispusiera de un perfil propio aprobado por el CCN, prevalecería el perfil y esta SoA se re-emitiría.
A6: Criterio de selección de medidas (art. 28.1) | B6: a) Activos que constituyen el sistema (inventario INV-01); b) Categoría del sistema: ALTA (art. 40 y Anexo I), con niveles por dimensión D=ALTO, I=ALTO, C=ALTO, A=ALTO, T=MEDIO; c) Decisiones del análisis de riesgos (AR-2026-01, MAGERIT v3 / PILAR, riesgo residual aceptado por el CSI el 30/06/2026).
A7: Regla de aplicación de cada medida | B7: Si la medida afecta a 'Categoría' (todas las dimensiones) se exige el nivel de la CATEGORÍA del sistema (ALTA). Si la medida afecta a una o varias dimensiones concretas, se exige el nivel MÁS ALTO de esas dimensiones (Anexo II, apdo. 2). Ej.: [op.exp.8] afecta sólo a T → nivel MEDIO → se exigen R1-R4 pero no R5; [mp.info.4] afecta sólo a T y sólo aplica en ALTO → NO APLICA en TechServ; [op.acc.1] afecta a T y A → ALTO.
A8: Declaración de Aplicabilidad (art. 28.2) | B8: Documento formalizado y firmado por la Responsable de Seguridad; revisado al menos anualmente y ante cambios significativos del sistema, del análisis de riesgos o de la categoría.
A9: Medidas compensatorias (art. 28.3) | B9: Cuando una medida o refuerzo no puede implantarse tal como lo describe el Anexo II, se sustituye por medidas compensatorias justificadas documentalmente en la hoja 'Medidas compensatorias' (ámbito, restricción, riesgo, medida, validación, mantenimiento), con aprobación del CSI y verificación en auditoría.
A10: Conformidad y auditoría | B10: Categoría ALTA → auditoría formal bienal (art. 31 y Anexo III) y Certificación de Conformidad por entidad acreditada por ENAC (art. 38; ITS de Conformidad, Res. 13/10/2016). Auditoría intermedia de seguimiento anual. Se usa CCN-STIC 808 como cuestionario de verificación y CCN-STIC 804 como guía de implantación.
A11: Instrucciones Técnicas de Seguridad aplicables | B11: ITS de Conformidad con el ENS; ITS de Auditoría de la Seguridad; ITS de Notificación de Incidentes de Seguridad (vía CCN-CERT / LUCIA, art. 33); ITS de Informe del Estado de la Seguridad (INES, art. 32).
A12: Guías CCN-STIC de referencia | B12: 800 (glosario), 801 (roles), 802 (auditoría), 803 (valoración), 804 (implantación), 805 (política), 806 (plan de adecuación), 808 (verificación), 809 (declaración/certificación), 810 (medidas en la nube), 811 (interconexión), 815 (métricas), 817 (ciberincidentes), 821 (normas de seguridad), 823 (cloud), 824 (informe estado seguridad), 825 (ENS ↔ ISO 27001), 827 (RD 311 categorización), 830 (ámbito y contratación).

Sheet Categorización
A1: Categorización del sistema PSTA – Anexo I RD 311/2022 (CCN-STIC 803 / 827)
A2: Criterio Anexo I: BAJO = perjuicio limitado · MEDIO = perjuicio grave · ALTO = perjuicio muy grave, sobre las funciones de la organización, los activos o las personas. El nivel de cada dimensión del sistema es el MÁXIMO de los activos esenciales; la categoría es ALTA si alguna dimensión es ALTO (art. 40).
A4: Tipo | B4: ID | C4: Activo esencial (servicio / información) | D4: Responsable de la Información / Servicio | E4: D | F4: I | G4: C | H4: A | I4: T | J4: Justificación de la valoración (Anexo I)
A5: Servicio | B5: S-01 | C5: Sede tributaria electrónica (autoliquidaciones, pagos, notificaciones) | D5: Consejería de Hacienda | E5: m | F5: ALTO | G5: ALTO | H5: ALTO | I5: MEDIO | J5: D: la interrupción en campaña impide el cumplimiento de obligaciones tributarias de >2M contribuyentes (perjuicio muy grave, Anexo I). I/A: la alteración o suplantación de una autoliquidación tiene efectos jurídicos directos. C: datos tributarios (art. 95 LGT). T: se exige reconstruir quién hizo qué, pero un fallo aislado del registro tiene consecuencias graves, no muy graves.
A6: Servicio | B6: S-02 | C6: Plataforma de gestión académica y becas | D6: Consejería de Educación | E6: MEDIO | F6: ALTO | G6: ALTO | H6: MEDIO | I6: MEDIO | J6: D: tolera 24-48 h de parada fuera de matriculación. I: la manipulación de expedientes/calificaciones tiene efectos legales. C: datos de menores y situación socioeconómica de familias. A/T: consecuencias graves pero recuperables.
A7: Servicio | B7: S-03 | C7: Gestión de expedientes de dependencia y prestaciones sociales | D7: Consejería de Bienestar Social | E7: MEDIO | F7: ALTO | G7: ALTO | H7: MEDIO | I7: MEDIO | J7: C: datos de salud y situación de vulnerabilidad (categorías especiales, art. 9 RGPD) → ALTO. I: la alteración de un grado de dependencia altera prestaciones económicas. D: proceso administrativo con tolerancia de 48 h.
A8: Servicio | B8: S-04 | C8: Servicios transversales (Directorio, correo corporativo, VPN, PKI interna, monitorización) | D8: TechServ (Responsable del Sistema) | E8: m | F8: ALTO | G8: ALTO | H8: ALTO | I8: MEDIO | J8: Hereda el máximo de los servicios que soporta (dependencia funcional, Anexo I apdo. 4).
A9: Información | B9: I-01 | C9: Datos tributarios y de recaudación | D9: Consejería de Hacienda | E9: MEDIO | F9: ALTO | G9: ALTO | H9: ALTO | I9: MEDIO | J9: Información con reserva legal (art. 95 LGT). Su divulgación causa perjuicio muy grave a los derechos de los contribuyentes.
A10: Información | B10: I-02 | C10: Datos de salud / dependencia (categoría especial) | D10: Consejería de Bienestar Social | E10: MEDIO | F10: ALTO | G10: ALTO | H10: MEDIO | I10: MEDIO | J10: Categoría especial de datos (art. 9 RGPD); DPIA realizada (REG-RGPD-07).
A11: Información | B11: I-03 | C11: Datos académicos y socioeconómicos de menores | D11: Consejería de Educación | E11: BAJO | F11: ALTO | G11: ALTO | H11: MEDIO | I11: MEDIO | J11: Datos de menores: divulgación con perjuicio muy grave para los afectados.
A12: Información | B12: I-04 | C12: Credenciales, claves criptográficas y configuración de seguridad | D12: TechServ | E12: ALTO | F12: ALTO | G12: ALTO | H12: ALTO | I12: MEDIO | J12: Su compromiso afecta a todos los servicios (activo de soporte crítico).
A13: RESULTADO | C13: Nivel del sistema por dimensión (fórmula: máximo de los activos) | E13: =IF(COUNTIF(E5:E12,"ALTO")>0,"ALTO",IF(COUNTIF(E5:E12,"MEDIO")>0,"MEDIO","BAJO")) -> ALTO | F13: =IF(COUNTIF(F5:F12,"ALTO")>0,"ALTO",IF(COUNTIF(F5:F12,"MEDIO")>0,"MEDIO","BAJO")) -> ALTO | G13: =IF(COUNTIF(G5:G12,"ALTO")>0,"ALTO",IF(COUNTIF(G5:G12,"MEDIO")>0,"MEDIO","BAJO")) -> ALTO | H13: =IF(COUNTIF(H5:H12,"ALTO")>0,"ALTO",IF(COUNTIF(H5:H12,"MEDIO")>0,"MEDIO","BAJO")) -> ALTO | I13: =IF(COUNTIF(I5:I12,"ALTO")>0,"ALTO",IF(COUNTIF(I5:I12,"MEDIO")>0,"MEDIO","BAJO")) -> MEDIO | J13: Calculado automáticamente a partir de la tabla. Debe coincidir con la decisión formal del CSI (fila siguiente).
A14: DECISIÓN CSI | C14: Nivel aprobado por el Comité de Seguridad (ACTA-CSI-2026-03) | E14: ALTO | F14: ALTO | G14: ALTO | H14: ALTO | I14: MEDIO | J14: Estos valores alimentan la hoja 'SoA ENS' (columna 'Nivel exigido'). Celdas editables (amarillo).
A15: CATEGORÍA | C15: Categoría del sistema (art. 40): ALTA si alguna dimensión es ALTO; MEDIA si alguna es MEDIO; BÁSICA en otro caso | E15: =IF(COUNTIF(E14:I14,"ALTO")>0,"ALTA",IF(COUNTIF(E14:I14,"MEDIO")>0,"MEDIA","BÁSICA")) -> ALTA
A17: Consecuencias de la categorización sobre la SoA
A18: • Medidas que afectan a 'Categoría' (todas las dimensiones): se exige el nivel ALTA → columna 'Nivel ALTO' del Anexo II.
A19: • Medidas que afectan a dimensiones concretas: se exige el máximo de los niveles de esas dimensiones. Con T = MEDIO: [op.exp.8] (T) → MEDIO (R1-R4, sin R5); [mp.info.4] (T, sólo ALTO) → NO APLICA; [op.acc.1] (T y A) → ALTO por A.
A20: • Cambio de nivel en cualquier dimensión ⇒ re-emisión de la SoA, revisión del análisis de riesgos y comunicación a las consejerías (art. 28 / Anexo II apdo. 2).
A21: • Categoría ALTA ⇒ certificación de conformidad obligatoria por entidad acreditada y auditoría bienal (art. 31 y 38; ITS Conformidad / Auditoría).

Sheet SoA ENS
A1: Marco / familia | B1: Código | C1: Medida de seguridad | D1: Dimensiones afectadas (Anexo II) | E1: Nivel BAJO | F1: Nivel MEDIO | G1: Nivel ALTO | H1: Nivel exigido a TechServ | I1: Regla aplicada | J1: Exigencia aplicable (Anexo II) | K1: Refuerzos exigidos (Rn) | L1: Refuerzos / alternativa elegida | M1: ¿Aplica? | N1: Justificación de aplicabilidad / exclusión | O1: Medidas ORGANIZATIVAS implantadasPortal de firma de normativas (registro de aceptación); banner de aviso en el inicio de sesión. | P1: Medidas TÉCNICAS implantadas | Q1: Medida compensatoria (ref.) | R1: Estado de implantación | S1: % implantación | T1: Evidencias / documentos | U1: Responsable | V1: Control ISO/IEC 27001:2022 equivalente (CCN-STIC 825) | W1: Guías CCN-STIC / verificación | X1: Observaciones / PTR
A2: Marco organizativo | B2: org.2 | C2: Normativa de seguridad | D2: Categoría | E2: aplica | F2: aplica | G2: aplica | H2: =IF('Categorización'!$E$15="ALTA","ALTO",IF('Categorización'!$E$15="MEDIA","MEDIO","BAJO")) -> ALTO | I2: Categoría del sistema = ALTA | J2: =IF(H2="ALTO",G2,IF(H2="MEDIO",F2,E2)) -> aplica | K2: — | L2: — | M2: SÍ | N2: APLICA: medida exigida para la categoría ALTA del sistema (afecta a todas las dimensiones). Exigencia: 'aplica'. Riesgos tratados según AR-2026-01. CCN-STIC 808: 3 requisitos de verificación (2 esenciales). | O2: Normativas de seguridad NOR-01 Uso aceptable de recursos TIC, NOR-02 Puesto de trabajo y teletrabajo, NOR-03 Dispositivos móviles, NOR-04 Clasificación y manejo de la información, NOR-05 Contraseñas y autenticación; régimen disciplinario vinculado al convenio y contratos. Aceptación firmada por todo el personal y terceros. | P2: Portal de firma de normativas (registro de aceptación); banner de aviso en el inicio de sesión. | Q2: — | R2: Implantada | S2: 1 | T2: NOR-01..05; REG-ACEPT-NOR (aceptaciones); PRO-RRHH-02 | U2: Responsable de Seguridad | V2: 5.1 Políticas; 5.10 Uso aceptable; 5.36 Cumplimiento de políticas; 6.7 Trabajo remoto; 7.7 Escritorio y pantalla despejados; 8.1 Dispositivos de usuario | W2: CCN-STIC 801, 805, 821, 804/808
A3: Marco organizativo | B3: org.3 | C3: Procedimientos de seguridad | D3: Categoría | E3: aplica | F3: aplica | G3: aplica | H3: =IF('Categorización'!$E$15="ALTA","ALTO",IF('Categorización'!$E$15="MEDIA","MEDIO","BAJO")) -> ALTO | I3: Categoría del sistema = ALTA | J3: =IF(H3="ALTO",G3,IF(H3="MEDIO",F3,E3)) -> aplica | K3: — | L3: — | M3: SÍ | N3: APLICA: medida exigida para la categoría ALTA del sistema (afecta a todas las dimensiones). Exigencia: 'aplica'. Riesgos tratados según AR-2026-01. CCN-STIC 808: 7 requisitos de verificación (2 esenciales). | O3: Catálogo de procedimientos operativos PRO-xx (altas/bajas de usuarios, copias, cambios, incidentes, parches, gestión de soportes, acceso físico, notificación a CCN-CERT, etc.) con propietario, revisión anual y validación por el Resp. de Seguridad. | P3: Repositorio documental con flujo de aprobación y control de versiones; enlaces desde la herramienta ITSM. | Q3: — | R3: Implantada | S3: 1 | T3: Índice documental IDX-01 (48 procedimientos); PRO-GEST-01 Gestión documental | U3: Responsable del Sistema | V3: 5.37 Procedimientos operativos documentados; 5.5 Contacto con autoridades; 5.14 Transferencia de información; 5.24 Planificación de la gestión de incidentes | W3: CCN-STIC 801, 805, 821, 804/808
A4: Marco organizativo | B4: org.4 | C4: Proceso de autorización | D4: Categoría | E4: aplica | F4: aplica | G4: aplica | H4: =IF('Categorización'!$E$15="ALTA","ALTO",IF('Categorización'!$E$15="MEDIA","MEDIO","BAJO")) -> ALTO | I4: Categoría del sistema = ALTA | J4: =IF(H4="ALTO",G4,IF(H4="MEDIO",F4,E4)) -> aplica | K4: — | L4: — | M4: SÍ | N4: APLICA: medida exigida para la categoría ALTA del sistema (afecta a todas las dimensiones). Exigencia: 'aplica'. Riesgos tratados según AR-2026-01. CCN-STIC 808: 10 requisitos de verificación (4 esenciales). | O4: Procedimiento de autorización PRO-AUT-01: entrada en producción de instalaciones, equipos, aplicaciones, interconexiones, medios de comunicación, soportes y sistemas de terceros; matriz de autorización (Resp. Sistema autoriza, Resp. Seguridad informa favorablemente). | P4: Flujo de autorización en ITSM (ServiceDesk) con evidencias adjuntas; CMDB bloquea activos no autorizados (estado 'pendiente de autorización'). | Q4: — | R4: Implantada | S4: 1 | T4: PRO-AUT-01; REG-AUT-2026 (registro de autorizaciones); tickets ITSM | U4: Responsable del Sistema | V4: 5.2 Roles y responsabilidades; 8.19 Instalación de software; 8.20 Seguridad de redes; 8.32 Gestión de cambios; 5.10 Uso aceptable | W4: CCN-STIC 801, 805, 821, 804/808
A5: Planificación | B5: op.pl.3 | C5: Adquisición de nuevos componentes | D5: Categoría | E5: aplica | F5: aplica | G5: aplica | H5: =IF('Categorización'!$E$15="ALTA","ALTO",IF('Categorización'!$E$15="MEDIA","MEDIO","BAJO")) -> ALTO | I5: Categoría del sistema = ALTA | J5: =IF(H5="ALTO",G5,IF(H5="MEDIO",F5,E5)) -> aplica | K5: — | L5: — | M5: SÍ | N5: APLICA: medida exigida para la categoría ALTA del sistema (afecta a todas las dimensiones). Exigencia: 'aplica'. Riesgos tratados según AR-2026-01. CCN-STIC 808: 4 requisitos de verificación (1 esenciales). | O5: Procedimiento de adquisición PRO-COMP-02: requisitos de seguridad en pliegos internos, preferencia por productos CPSTIC, evaluación por el Resp. de Seguridad antes de la compra; alineado con la planificación de capacidad. | P5: Checklist de requisitos de seguridad en el módulo de compras del ERP. | Q5: — | R5: Implantada | S5: 1 | T5: PRO-COMP-02; REG-COMP-2026 (evaluaciones) | U5: Compras / Resp. Seguridad | V5: 5.8 Seguridad en la gestión de proyectos; 5.19/5.20 Seguridad en las relaciones con proveedores; 8.29 Pruebas de seguridad en desarrollo y aceptación | W5: CCN-STIC 803, 806, 827, 804/808
A6: Control de acceso | B6: op.acc.3 | C6: Segregación de funciones y tareas | D6: ICAT | E6: n.a. | F6: aplica | G6: + R1 | H6: =IF(OR('Categorización'!F$14="ALTO",'Categorización'!G$14="ALTO",'Categorización'!H$14="ALTO",'Categorización'!I$14="ALTO"),"ALTO",IF(OR('Categorización'!F$14="MEDIO",'Categorización'!G$14="MEDIO",'Categorización'!H$14="MEDIO",'Categorización'!I$14="MEDIO"),"MEDIO","BAJO")) -> ALTO | I6: máx(I=ALTO, C=ALTO, A=ALTO, T=MEDIO) = ALTO | J6: =IF(H6="ALTO",G6,IF(H6="MEDIO",F6,E6)) -> + R1 | K6: R1 Segregación rigurosa | L6: — | M6: SÍ | N6: APLICA: medida vinculada a la(s) dimensión(es) ICAT; nivel exigido ALTO (máx(I=ALTO, C=ALTO, A=ALTO, T=MEDIO) = ALTO). Exigencia: '+ R1'. Riesgos tratados según AR-2026-01. CCN-STIC 808: 6 requisitos de verificación (0 esenciales). | O6: Segregación rigurosa (R1): desarrollo / operación / auditoría de seguridad en equipos distintos; configuración de seguridad ≠ operación; nadie audita su propia actividad; matriz SoD revisada semestralmente. | P6: Controles SoD en IGA (reglas de incompatibilidad); entornos separados; acceso de auditoría de solo lectura a logs (SIEM). | Q6: — | R6: Implantada | S6: 1 | T6: MAT-SOD-01; informe semestral SoD (IGA) | U6: Responsable de Seguridad | V6: 5.3 Segregación de funciones; 8.2 Derechos de acceso privilegiado | W6: CCN-STIC 804/808, 821
A7: Control de acceso | B7: op.acc.4 | C7: Proceso de gestión de derechos de acceso | D7: ICAT | E7: aplica | F7: aplica | G7: aplica | H7: =IF(OR('Categorización'!F$14="ALTO",'Categorización'!G$14="ALTO",'Categorización'!H$14="ALTO",'Categorización'!I$14="ALTO"),"ALTO",IF(OR('Categorización'!F$14="MEDIO",'Categorización'!G$14="MEDIO",'Categorización'!H$14="MEDIO",'Categorización'!I$14="MEDIO"),"MEDIO","BAJO")) -> ALTO | I7: máx(I=ALTO, C=ALTO, A=ALTO, T=MEDIO) = ALTO | J7: =IF(H7="ALTO",G7,IF(H7="MEDIO",F7,E7)) -> aplica | K7: — | L7: — | M7: SÍ | N7: APLICA: medida vinculada a la(s) dimensión(es) ICAT; nivel exigido ALTO (máx(I=ALTO, C=ALTO, A=ALTO, T=MEDIO) = ALTO). Exigencia: 'aplica'. Riesgos tratados según AR-2026-01. CCN-STIC 808: 6 requisitos de verificación (4 esenciales). | O7: Procedimiento PRO-IAM-03: solicitud-aprobación-provisión-revisión-revocación; aprobación del propietario del activo; revisión semestral de accesos (recertificación) y trimestral de privilegiados. | P7: Workflow de aprobación en IGA; recertificación automática; revocación inmediata al causar baja en RRHH. | Q7: — | R7: Implantada | S7: 1 | T7: PRO-IAM-03; campañas de recertificación 2026-S1; tickets | U7: Responsable del Sistema | V7: 5.18 Derechos de acceso; 8.2 Derechos de acceso privilegiado; 5.15 Control de acceso | W7: CCN-STIC 804/808, 821
A8: Explotación | B8: op.exp.1 | C8: Inventario de activos | D8: Categoría | E8: aplica | F8: aplica | G8: aplica | H8: =IF('Categorización'!$E$15="ALTA","ALTO",IF('Categorización'!$E$15="MEDIA","MEDIO","BAJO")) -> ALTO | I8: Categoría del sistema = ALTA | J8: =IF(H8="ALTO",G8,IF(H8="MEDIO",F8,E8)) -> aplica | K8: — | L8: — | M8: SÍ | N8: APLICA: medida exigida para la categoría ALTA del sistema (afecta a todas las dimensiones). Exigencia: 'aplica'. Riesgos tratados según AR-2026-01. CCN-STIC 808: 3 requisitos de verificación (2 esenciales). | O8: Inventario de activos INV-01 (hardware, software, información, servicios, comunicaciones, instalaciones, personal) con responsable, ubicación, categoría y dependencias; actualización con cada cambio autorizado; reconciliación trimestral. | P8: CMDB (ITSM) alimentada por descubrimiento automático (agentes + escaneo de red) y gestión de licencias; SBOM para software propio. | Q8: — | R8: Implantada | S8: 1 | T8: INV-01 (export CMDB 09/2026); PRO-INV-01; informe de reconciliación | U8: Jefe de Operaciones TI | V8: 5.9 Inventario de información y otros activos; 5.12 Clasificación | W8: CCN-STIC 804/808, 817, 5xx/6xx
A9: Explotación | B9: op.exp.2 | C9: Configuración de seguridad | D9: Categoría | E9: aplica | F9: aplica | G9: aplica | H9: =IF('Categorización'!$E$15="ALTA","ALTO",IF('Categorización'!$E$15="MEDIA","MEDIO","BAJO")) -> ALTO | I9: Categoría del sistema = ALTA | J9: =IF(H9="ALTO",G9,IF(H9="MEDIO",F9,E9)) -> aplica | K9: — | L9: — | M9: SÍ | N9: APLICA: medida exigida para la categoría ALTA del sistema (afecta a todas las dimensiones). Exigencia: 'aplica'. Riesgos tratados según AR-2026-01. CCN-STIC 808: 4 requisitos de verificación (3 esenciales). | O9: Guías de bastionado por tecnología (CCN-STIC 5xx/6xx y CIS Benchmarks) aprobadas; mínima funcionalidad; cuentas por defecto retiradas; principio de seguridad por defecto; checklist obligatoria antes del paso a producción. | P9: Imágenes maestras bastionadas (golden images); GPO/Ansible para configuración; escaneo de cumplimiento de configuración (SCAP) semanal; DLP en endpoints. | Q9: — | R9: Implantada | S9: 1 | T9: PRO-HARD-01; checklists CFG-xx; informes SCAP | U9: Jefe de Operaciones TI | V9: 8.9 Gestión de la configuración; 8.19 Instalación de software; 8.12 Prevención de fuga de datos | W9: CCN-STIC 804/808, 817, 5xx/6xx
A10: Explotación | B10: op.exp.5 | C10: Gestión de cambios | D10: Categoría | E10: n.a. | F10: aplica | G10: + R1 | H10: =IF('Categorización'!$E$15="ALTA","ALTO",IF('Categorización'!$E$15="MEDIA","MEDIO","BAJO")) -> ALTO | I10: Categoría del sistema = ALTA | J10: =IF(H10="ALTO",G10,IF(H10="MEDIO",F10,E10)) -> + R1 | K10: R1 Prevención de fallos | L10: — | M10: SÍ | N10: APLICA: medida exigida para la categoría ALTA del sistema (afecta a todas las dimensiones). Exigencia: '+ R1'. Riesgos tratados según AR-2026-01. CCN-STIC 808: 10 requisitos de verificación (0 esenciales). | O10: Gestión de cambios PRO-CHG-01: CAB semanal, evaluación de impacto en seguridad, plan de marcha atrás, cambios de emergencia; prevención de fallos (R1) mediante pruebas obligatorias y análisis de riesgos del cambio. | P10: Módulo de cambios en ITSM con aprobación electrónica; entornos dev/pre/pro; despliegues automatizados con rollback. | Q10: — | R10: Implantada | S10: 1 | T10: PRO-CHG-01; actas CAB; RFC-2026-xxx | U10: Responsable del Sistema | V10: 8.32 Gestión de cambios; 8.29 Pruebas de seguridad; 8.31 Separación de entornos | W10: CCN-STIC 804/808, 817, 5xx/6xx
A11: Explotación | B11: op.exp.9 | C11: Registro de la gestión de incidentes | D11: Categoría | E11: aplica | F11: aplica | G11: aplica | H11: =IF('Categorización'!$E$15="ALTA","ALTO",IF('Categorización'!$E$15="MEDIA","MEDIO","BAJO")) -> ALTO | I11: Categoría del sistema = ALTA | J11: =IF(H11="ALTO",G11,IF(H11="MEDIO",F11,E11)) -> aplica | K11: — | L11: — | M11: SÍ | N11: APLICA: medida exigida para la categoría ALTA del sistema (afecta a todas las dimensiones). Exigencia: 'aplica'. Riesgos tratados según AR-2026-01. CCN-STIC 808: 5 requisitos de verificación (3 esenciales). | O11: Registro de la gestión de incidentes: apertura, cronología, decisiones, evidencias, cierre, lecciones aprendidas; alimenta el análisis de riesgos y las métricas; conservación 5 años. | P11: Módulo de incidentes en ITSM enlazado con el SIEM; custodia de evidencias con cadena de custodia (hash, firma) según PRO-INC-02. | Q11: — | R11: Implantada | S11: 1 | T11: REG-INC-2026 (37 incidentes); informes post-incidente; PRO-INC-02 | U11: SOC (SecOps Iberia) / Resp. Seguridad | V11: 5.26 Respuesta a incidentes; 5.27 Aprender de incidentes; 5.28 Recogida de evidencias | W11: CCN-STIC 804/808, 817, 5xx/6xx
A12: Recursos externos | B12: op.ext.1 | C12: Contratación y acuerdos de nivel de servicio | D12: Categoría | E12: n.a. | F12: aplica | G12: aplica | H12: =IF('Categorización'!$E$15="ALTA","ALTO",IF('Categorización'!$E$15="MEDIA","MEDIO","BAJO")) -> ALTO | I12: Categoría del sistema = ALTA | J12: =IF(H12="ALTO",G12,IF(H12="MEDIO",F12,E12)) -> aplica | K12: — | L12: — | M12: SÍ | N12: APLICA: medida exigida para la categoría ALTA del sistema (afecta a todas las dimensiones). Exigencia: 'aplica'. Riesgos tratados según AR-2026-01. CCN-STIC 808: 2 requisitos de verificación (0 esenciales). | O12: Contratación de terceros con cláusulas ENS/RGPD (modelo CON-SEC-01): roles y responsabilidades, medidas exigidas, ANS con penalizaciones, derecho de auditoría, notificación de incidentes ≤24 h, subcontratación autorizada; acuerdos de confidencialidad. | P12: Registro de proveedores en el ERP con estado de evaluación de seguridad; portal de intercambio seguro. | Q12: — | R12: Implantada | S12: 1 | T12: Contratos SecOps Iberia, NubeAdmin, custodia de soportes; CON-SEC-01; REG-PROV-01 | U12: Compras / Resp. Seguridad | V12: 5.19 Seguridad en relaciones con proveedores; 5.20 Seguridad en acuerdos con proveedores; 6.6 Acuerdos de confidencialidad; 5.14 Transferencia de información | W12: CCN-STIC 811, 830, 804/808
A13: Recursos externos | B13: op.ext.2 | C13: Gestión diaria | D13: Categoría | E13: n.a. | F13: aplica | G13: aplica | H13: =IF('Categorización'!$E$15="ALTA","ALTO",IF('Categorización'!$E$15="MEDIA","MEDIO","BAJO")) -> ALTO | I13: Categoría del sistema = ALTA | J13: =IF(H13="ALTO",G13,IF(H13="MEDIO",F13,E13)) -> aplica | K13: — | L13: — | M13: SÍ | N13: APLICA: medida exigida para la categoría ALTA del sistema (afecta a todas las dimensiones). Exigencia: 'aplica'. Riesgos tratados según AR-2026-01. CCN-STIC 808: 4 requisitos de verificación (0 esenciales). | O13: Gestión diaria de servicios externos (PRO-PROV-02): responsable interno por proveedor, seguimiento mensual de ANS e indicadores, gestión de incidencias y cambios del proveedor, reuniones de servicio. | P13: Cuadro de mando de ANS (Power BI) con datos del ITSM; canal cifrado para coordinación de incidentes. | Q13: — | R13: Implantada | S13: 1 | T13: Informes mensuales de servicio; actas de seguimiento | U13: Jefe de Operaciones TI | V13: 5.22 Seguimiento, revisión y gestión de cambios de servicios de proveedores | W13: CCN-STIC 811, 830, 804/808
A14: Continuidad del servicio | B14: op.cont.2 | C14: Plan de continuidad | D14: D | E14: n.a. | F14: n.a. | G14: aplica | H14: =IF(OR('Categorización'!E$14="ALTO"),"ALTO",IF(OR('Categorización'!E$14="MEDIO"),"MEDIO","BAJO")) -> ALTO | I14: máx(D=ALTO) = ALTO | J14: =IF(H14="ALTO",G14,IF(H14="MEDIO",F14,E14)) -> aplica | K14: — | L14: — | M14: SÍ | N14: APLICA: medida vinculada a la(s) dimensión(es) D; nivel exigido ALTO (máx(D=ALTO) = ALTO). Exigencia: 'aplica'. Riesgos tratados según AR-2026-01. CCN-STIC 808: 7 requisitos de verificación (0 esenciales). | O14: Plan de Continuidad PCN-01 y Plan de Recuperación ante Desastres DRP-01: activación, roles, comunicación, procedimientos de recuperación por servicio, retorno a la normalidad; plan de emergencia y contingencia integrado; revisión anual. | P14: Replicación síncrona de almacenamiento entre CPD (14 km), orquestación de conmutación, copias inmutables externas; runbooks automatizados. | Q14: — | R14: Implantada | S14: 1 | T14: PCN-01 v3; DRP-01; árbol de llamadas | U14: Responsable del Sistema | V14: 5.29 Seguridad durante la disrupción; 5.30 Preparación TIC continuidad | W14: CCN-STIC 804/808; ISO 22301
A15: Continuidad del servicio | B15: op.cont.3 | C15: Pruebas periódicas | D15: D | E15: n.a. | F15: n.a. | G15: aplica | H15: =IF(OR('Categorización'!E$14="ALTO"),"ALTO",IF(OR('Categorización'!E$14="MEDIO"),"MEDIO","BAJO")) -> ALTO | I15: máx(D=ALTO) = ALTO | J15: =IF(H15="ALTO",G15,IF(H15="MEDIO",F15,E15)) -> aplica | K15: — | L15: — | M15: SÍ | N15: APLICA: medida vinculada a la(s) dimensión(es) D; nivel exigido ALTO (máx(D=ALTO) = ALTO). Exigencia: 'aplica'. Riesgos tratados según AR-2026-01. CCN-STIC 808: 5 requisitos de verificación (0 esenciales). | O15: Programa anual de pruebas: prueba de mesa (T1), conmutación parcial de servicio (T2), conmutación completa de CPD (T4); informe y acciones correctivas; participación de las consejerías. | P15: Entorno de pruebas de recuperación aislado; automatización de restauraciones. | Q15: — | R15: Implantada | S15: 1 | T15: REG-CONT-03 (pruebas 2025-2026); informe de conmutación 11/2025 | U15: Jefe de Operaciones TI | V15: 5.30 Preparación TIC continuidad (pruebas); 8.14 Redundancia | W15: CCN-STIC 804/808; ISO 22301
A16: Continuidad del servicio | B16: op.cont.4 | C16: Medios alternativos | D16: D | E16: n.a. | F16: n.a. | G16: aplica | H16: =IF(OR('Categorización'!E$14="ALTO"),"ALTO",IF(OR('Categorización'!E$14="MEDIO"),"MEDIO","BAJO")) -> ALTO | I16: máx(D=ALTO) = ALTO | J16: =IF(H16="ALTO",G16,IF(H16="MEDIO",F16,E16)) -> aplica | K16: — | L16: — | M16: SÍ | N16: APLICA: medida vinculada a la(s) dimensión(es) D; nivel exigido ALTO (máx(D=ALTO) = ALTO). Exigencia: 'aplica'. Riesgos tratados según AR-2026-01. CCN-STIC 808: 3 requisitos de verificación (0 esenciales). | O16: Medios alternativos garantizados: CPD de respaldo activo-pasivo, personal alternativo formado (matriz de sustitución), instalaciones alternativas de trabajo (teletrabajo seguro + oficina de respaldo), proveedores alternativos de comunicaciones, contratos de continuidad con SecOps y NubeAdmin. | P16: Doble operador de comunicaciones con rutas físicas distintas; capacidad de reserva en cloud ENS ALTA; VPN dimensionada para el 100 % de la plantilla. | Q16: — | R16: Implantada | S16: 1 | T16: DRP-01 anexo B (medios alternativos); contratos; MAT-SUST-01 | U16: Responsable del Sistema | V16: 8.14 Redundancia de instalaciones de tratamiento; 5.30 Preparación TIC continuidad | W16: CCN-STIC 804/808; ISO 22301
A17: Protección de las instalaciones e infraestructuras | B17: mp.if.1 | C17: Áreas separadas y con control de acceso | D17: Categoría | E17: aplica | F17: aplica | G17: aplica | H17: =IF('Categorización'!$E$15="ALTA","ALTO",IF('Categorización'!$E$15="MEDIA","MEDIO","BAJO")) -> ALTO | I17: Categoría del sistema = ALTA | J17: =IF(H17="ALTO",G17,IF(H17="MEDIO",F17,E17)) -> aplica | K17: — | L17: — | M17: SÍ | N17: APLICA: medida exigida para la categoría ALTA del sistema (afecta a todas las dimensiones). Exigencia: 'aplica'. Riesgos tratados según AR-2026-01. CCN-STIC 808: 4 requisitos de verificación (2 esenciales). | O17: Zonificación de instalaciones (pública, oficinas, salas técnicas, CPD) con control de acceso por zona y autorización nominal; visitantes acompañados; revisión trimestral de accesos. | P17: Control de acceso con tarjeta + PIN en oficinas; tarjeta + biometría en CPD y salas técnicas; esclusa en CPD; CCTV con retención 30 días. | Q17: — | R17: Implantada | S17: 1 | T17: PRO-FIS-01; planos de zonificación; REG-ACC-FIS | U17: Facilities / Resp. del Sistema | V17: 7.1 Perímetros de seguridad física; 7.2 Entradas físicas; 7.3 Oficinas, salas e instalaciones; 7.4 Vigilancia física; 7.6 Trabajo en áreas seguras | W17: CCN-STIC 804/808
A18: Protección de las instalaciones e infraestructuras | B18: mp.if.2 | C18: Identificación de las personas | D18: Categoría | E18: aplica | F18: aplica | G18: aplica | H18: =IF('Categorización'!$E$15="ALTA","ALTO",IF('Categorización'!$E$15="MEDIA","MEDIO","BAJO")) -> ALTO | I18: Categoría del sistema = ALTA | J18: =IF(H18="ALTO",G18,IF(H18="MEDIO",F18,E18)) -> aplica | K18: — | L18: — | M18: SÍ | N18: APLICA: medida exigida para la categoría ALTA del sistema (afecta a todas las dimensiones). Exigencia: 'aplica'. Riesgos tratados según AR-2026-01. CCN-STIC 808: 3 requisitos de verificación (1 esenciales). | O18: Identificación de todas las personas: tarjeta visible, registro de visitas (nombre, empresa, motivo, hora, acompañante), identificación del personal de proveedores. | P18: Sistema de gestión de visitas con registro electrónico; tornos en recepción. | Q18: — | R18: Implantada | S18: 1 | T18: REG-VIS-2026; PRO-FIS-01 | U18: Facilities / Resp. del Sistema | V18: 7.2 Controles físicos de entrada; 7.4 Vigilancia de la seguridad física | W18: CCN-STIC 804/808
A19: Protección de las instalaciones e infraestructuras | B19: mp.if.3 | C19: Acondicionamiento de los locales | D19: Categoría | E19: aplica | F19: aplica | G19: aplica | H19: =IF('Categorización'!$E$15="ALTA","ALTO",IF('Categorización'!$E$15="MEDIA","MEDIO","BAJO")) -> ALTO | I19: Categoría del sistema = ALTA | J19: =IF(H19="ALTO",G19,IF(H19="MEDIO",F19,E19)) -> aplica | K19: — | L19: — | M19: SÍ | N19: APLICA: medida exigida para la categoría ALTA del sistema (afecta a todas las dimensiones). Exigencia: 'aplica'. Riesgos tratados según AR-2026-01. CCN-STIC 808: 5 requisitos de verificación (2 esenciales). | O19: Acondicionamiento de locales según buenas prácticas (TIA-942 Tier III en CPD): temperatura y humedad controladas, protección del cableado, protección frente a interferencias, no señalización de la sala. | P19: Climatización redundante N+1; monitorización ambiental (DCIM) con alertas; cableado estructurado en bandejas cerradas y etiquetado. | Q19: — | R19: Implantada | S19: 1 | T19: Informe DCIM; certificado de instalación | U19: Facilities / Resp. del Sistema | V19: 7.5 Protección contra amenazas físicas y ambientales; 7.8 Ubicación y protección de equipos; 7.12 Seguridad del cableado | W19: CCN-STIC 804/808
A20: Protección de las instalaciones e infraestructuras | B20: mp.if.5 | C20: Protección frente a incendios | D20: D | E20: aplica | F20: aplica | G20: aplica | H20: =IF(OR('Categorización'!E$14="ALTO"),"ALTO",IF(OR('Categorización'!E$14="MEDIO"),"MEDIO","BAJO")) -> ALTO | I20: máx(D=ALTO) = ALTO | J20: =IF(H20="ALTO",G20,IF(H20="MEDIO",F20,E20)) -> aplica | K20: — | L20: — | M20: SÍ | N20: APLICA: medida vinculada a la(s) dimensión(es) D; nivel exigido ALTO (máx(D=ALTO) = ALTO). Exigencia: 'aplica'. Riesgos tratados según AR-2026-01. CCN-STIC 808: 3 requisitos de verificación (3 esenciales). | O20: Protección contra incendios conforme a normativa (CTE, RIPCI): plan de autoprotección, inspecciones anuales, formación de equipos de emergencia. | P20: Detección temprana por aspiración (VESDA), extinción por gas inerte en CPD, extintores y BIE en oficinas, sectorización RF-90. | Q20: — | R20: Implantada | S20: 1 | T20: Certificado de mantenimiento PCI 2026; plan de autoprotección | U20: Facilities / Resp. del Sistema | V20: 7.5 Protección contra amenazas físicas y ambientales | W20: CCN-STIC 804/808
A21: Protección de las instalaciones e infraestructuras | B21: mp.if.7 | C21: Registro de entrada y salida de equipamiento | D21: Categoría | E21: aplica | F21: aplica | G21: aplica | H21: =IF('Categorización'!$E$15="ALTA","ALTO",IF('Categorización'!$E$15="MEDIA","MEDIO","BAJO")) -> ALTO | I21: Categoría del sistema = ALTA | J21: =IF(H21="ALTO",G21,IF(H21="MEDIO",F21,E21)) -> aplica | K21: — | L21: — | M21: SÍ | N21: APLICA: medida exigida para la categoría ALTA del sistema (afecta a todas las dimensiones). Exigencia: 'aplica'. Riesgos tratados según AR-2026-01. CCN-STIC 808: 2 requisitos de verificación (1 esenciales). | O21: Registro de entrada y salida de equipamiento (PRO-FIS-02): autorización previa, identificación del equipo (etiqueta/serie), portador, fecha/hora, destino. | P21: Registro electrónico en el ITSM enlazado con la CMDB; etiquetas RFID en activos del CPD con detección en puertas. | Q21: — | R21: Implantada | S21: 1 | T21: REG-EQ-2026; PRO-FIS-02 | U21: Facilities / Resp. del Sistema | V21: 7.2 Controles físicos de entrada; 7.9 Seguridad de activos fuera de las instalaciones; 7.10 Soportes de almacenamiento | W21: CCN-STIC 804/808
A22: Gestión del personal | B22: mp.per.1 | C22: Caracterización del puesto de trabajo | D22: Categoría | E22: n.a. | F22: aplica | G22: aplica | H22: =IF('Categorización'!$E$15="ALTA","ALTO",IF('Categorización'!$E$15="MEDIA","MEDIO","BAJO")) -> ALTO | I22: Categoría del sistema = ALTA | J22: =IF(H22="ALTO",G22,IF(H22="MEDIO",F22,E22)) -> aplica | K22: — | L22: — | M22: SÍ | N22: APLICA: medida exigida para la categoría ALTA del sistema (afecta a todas las dimensiones). Exigencia: 'aplica'. Riesgos tratados según AR-2026-01. CCN-STIC 808: 2 requisitos de verificación (0 esenciales). | O22: Descripción de cada puesto con responsabilidades de seguridad, nivel de acceso a información y requisitos (habilitación, antecedentes cuando lo permite la ley, cláusulas); selección con verificación de referencias y titulación; puestos de confianza (administradores, SOC) con requisitos reforzados. | P22: Perfiles de puesto en el sistema de RRHH vinculados a roles IGA. | Q22: — | R22: Implantada | S22: 1 | T22: Catálogo de puestos CAT-PUE-01; PRO-RRHH-01 selección | U22: Dirección de Personas (RRHH) | V22: 6.1 Selección (cribado); 6.2 Términos y condiciones de empleo; 5.2 Roles y responsabilidades | W22: CCN-STIC 804/808, 821
A23: Gestión del personal | B23: mp.per.3 | C23: Concienciación | D23: Categoría | E23: aplica | F23: aplica | G23: aplica | H23: =IF('Categorización'!$E$15="ALTA","ALTO",IF('Categorización'!$E$15="MEDIA","MEDIO","BAJO")) -> ALTO | I23: Categoría del sistema = ALTA | J23: =IF(H23="ALTO",G23,IF(H23="MEDIO",F23,E23)) -> aplica | K23: — | L23: — | M23: SÍ | N23: APLICA: medida exigida para la categoría ALTA del sistema (afecta a todas las dimensiones). Exigencia: 'aplica'. Riesgos tratados según AR-2026-01. CCN-STIC 808: 4 requisitos de verificación (3 esenciales). | O23: Programa de concienciación anual: normativa, gestión de incidentes (cómo reportar), phishing, uso de dispositivos; sesiones de acogida; campañas trimestrales; medición de eficacia. | P23: Plataforma de e-learning y simulaciones de phishing (tasa de clic 3,1 % en 2026-Q2); comunicaciones internas. | Q23: — | R23: Implantada | S23: 1 | T23: PLAN-CONC-2026; registros de asistencia; informes de simulación | U23: Responsable de Seguridad | V23: 6.3 Concienciación, educación y formación en seguridad | W23: CCN-STIC 804/808, 821
A24: Gestión del personal | B24: mp.per.4 | C24: Formación | D24: Categoría | E24: aplica | F24: aplica | G24: aplica | H24: =IF('Categorización'!$E$15="ALTA","ALTO",IF('Categorización'!$E$15="MEDIA","MEDIO","BAJO")) -> ALTO | I24: Categoría del sistema = ALTA | J24: =IF(H24="ALTO",G24,IF(H24="MEDIO",F24,E24)) -> aplica | K24: — | L24: — | M24: SÍ | N24: APLICA: medida exigida para la categoría ALTA del sistema (afecta a todas las dimensiones). Exigencia: 'aplica'. Riesgos tratados según AR-2026-01. CCN-STIC 808: 6 requisitos de verificación (2 esenciales). | O24: Plan de formación específico por rol (administradores, desarrolladores, SOC, gestores): configuración segura, detección y reacción a incidentes, gestión de la información y soportes, desarrollo seguro; formación ENS (CCN) para el equipo de seguridad. | P24: Registro de competencias en RRHH; certificaciones (CCN-CERT Ángeles, ISO 27001 LA, SANS). | Q24: — | R24: Implantada | S24: 1 | T24: PLAN-FORM-2026; registros de formación; matriz de competencias | U24: Dirección de Personas (RRHH) | V24: 6.3 Concienciación, educación y formación; Cl. 7.2 Competencia | W24: CCN-STIC 804/808, 821
A25: Protección de las comunicaciones | B25: mp.com.1 | C25: Perímetro seguro | D25: Categoría | E25: aplica | F25: aplica | G25: aplica | H25: =IF('Categorización'!$E$15="ALTA","ALTO",IF('Categorización'!$E$15="MEDIA","MEDIO","BAJO")) -> ALTO | I25: Categoría del sistema = ALTA | J25: =IF(H25="ALTO",G25,IF(H25="MEDIO",F25,E25)) -> aplica | K25: — | L25: — | M25: SÍ | N25: APLICA: medida exigida para la categoría ALTA del sistema (afecta a todas las dimensiones). Exigencia: 'aplica'. Riesgos tratados según AR-2026-01. CCN-STIC 808: 4 requisitos de verificación (3 esenciales). | O25: Perímetro seguro: toda conexión al exterior pasa por cortafuegos; flujos autorizados y documentados; revisión trimestral de reglas; dos líneas de defensa de fabricantes distintos. | P25: Cortafuegos NG en alta disponibilidad (CPSTIC), IPS, DMZ multicapa, proxy saliente, DNS seguro; gestión de reglas con herramienta de análisis. | Q25: — | R25: Implantada | S25: 1 | T25: ARQ-02; REG-FW-REV (revisiones trimestrales) | U25: Jefe de Operaciones TI | V25: 8.20 Seguridad de redes; 8.21 Seguridad de servicios de red; 8.22 Segregación de redes | W25: CCN-STIC 807, 811, 804/808
A26: Protección de los soportes de información | B26: mp.si.3 | C26: Custodia | D26: Categoría | E26: aplica | F26: aplica | G26: aplica | H26: =IF('Categorización'!$E$15="ALTA","ALTO",IF('Categorización'!$E$15="MEDIA","MEDIO","BAJO")) -> ALTO | I26: Categoría del sistema = ALTA | J26: =IF(H26="ALTO",G26,IF(H26="MEDIO",F26,E26)) -> aplica | K26: — | L26: — | M26: SÍ | N26: APLICA: medida exigida para la categoría ALTA del sistema (afecta a todas las dimensiones). Exigencia: 'aplica'. Riesgos tratados según AR-2026-01. CCN-STIC 808: 3 requisitos de verificación (1 esenciales). | O26: Custodia de soportes: control de acceso a armarios ignífugos y sala de soportes, responsable de custodia, registro de entrega/devolución, respeto de condiciones del fabricante. | P26: Armarios ignífugos con cerradura electrónica y registro; sala de soportes bajo control de acceso biométrico; custodia externa con empresa certificada. | Q26: — | R26: Implantada | S26: 1 | T26: PRO-SOP-01; REG-CUST-SOP | U26: Jefe de Operaciones TI | V26: 7.10 Soportes de almacenamiento; 5.9 Inventario; 5.10 Uso aceptable | W26: CCN-STIC 807, 804/808
A27: Protección de los soportes de información | B27: mp.si.4 | C27: Transporte | D27: Categoría | E27: aplica | F27: aplica | G27: aplica | H27: =IF('Categorización'!$E$15="ALTA","ALTO",IF('Categorización'!$E$15="MEDIA","MEDIO","BAJO")) -> ALTO | I27: Categoría del sistema = ALTA | J27: =IF(H27="ALTO",G27,IF(H27="MEDIO",F27,E27)) -> aplica | K27: — | L27: — | M27: SÍ | N27: APLICA: medida exigida para la categoría ALTA del sistema (afecta a todas las dimensiones). Exigencia: 'aplica'. Riesgos tratados según AR-2026-01. CCN-STIC 808: 6 requisitos de verificación (1 esenciales). | O27: Transporte de soportes (PRO-SOP-02): registro de salida/entrada, responsable designado, cifrado, precinto, empresa de transporte con contrato de seguridad, verificación de recepción. | P27: Maletines con cierre y precinto numerado; geolocalización del transporte; cinta cifrada. | Q27: — | R27: Implantada | S27: 1 | T27: REG-TRANS-SOP; contrato de custodia externa | U27: Jefe de Operaciones TI | V27: 7.10 Soportes de almacenamiento; 7.9 Activos fuera de las instalaciones; 5.14 Transferencia | W27: CCN-STIC 807, 804/808
A28: Protección de la información | B28: mp.info.1 | C28: Datos personales | D28: Categoría | E28: aplica | F28: aplica | G28: aplica | H28: =IF('Categorización'!$E$15="ALTA","ALTO",IF('Categorización'!$E$15="MEDIA","MEDIO","BAJO")) -> ALTO | I28: Categoría del sistema = ALTA | J28: =IF(H28="ALTO",G28,IF(H28="MEDIO",F28,E28)) -> aplica | K28: — | L28: — | M28: SÍ | N28: APLICA: medida exigida para la categoría ALTA del sistema (afecta a todas las dimensiones). Exigencia: 'aplica'. Riesgos tratados según AR-2026-01. CCN-STIC 808: 8 requisitos de verificación (3 esenciales). | O28: Cumplimiento RGPD/LOPDGDD: registro de actividades de tratamiento, contratos de encargado con las consejerías, DPIA para S-02 y S-03, DPD nombrado, procedimiento de brechas (72 h a la AEPD vía el responsable), minimización y limitación de acceso; coordinación DPD–Resp. Seguridad. | P28: Cifrado y seudonimización de datos de categoría especial en BD; enmascaramiento en entornos no productivos; registro de accesos a datos personales (auditoría en BD). | Q28: — | R28: Implantada | S28: 1 | T28: RAT-2026; DPIA-S02, DPIA-S03; contratos de encargado; PRO-BRECHA-01 | U28: DPD / Resp. Seguridad | V28: 5.34 Privacidad y protección de la PII; 5.31 Requisitos legales; 8.11 Enmascaramiento | W28: CCN-STIC 807, 804/808
A29: Protección de los servicios | B29: mp.s.1 | C29: Protección del correo electrónico | D29: Categoría | E29: aplica | F29: aplica | G29: aplica | H29: =IF('Categorización'!$E$15="ALTA","ALTO",IF('Categorización'!$E$15="MEDIA","MEDIO","BAJO")) -> ALTO | I29: Categoría del sistema = ALTA | J29: =IF(H29="ALTO",G29,IF(H29="MEDIO",F29,E29)) -> aplica | K29: — | L29: — | M29: SÍ | N29: APLICA: medida exigida para la categoría ALTA del sistema (afecta a todas las dimensiones). Exigencia: 'aplica'. Riesgos tratados según AR-2026-01. CCN-STIC 808: 6 requisitos de verificación (4 esenciales). | O29: Protección del correo: normas de uso, prohibición de reenvío automático externo, cifrado para información CONFIDENCIAL/RESERVADA, concienciación anti-phishing. | P29: Pasarela de correo con antispam/antimalware/sandbox; SPF, DKIM, DMARC (p=reject); cifrado S/MIME y TLS obligatorio con las consejerías; DLP saliente; limpieza de metadatos. | Q29: — | R29: Implantada | S29: 1 | T29: Configuración de pasarela; informe DMARC; NOR-01 | U29: Jefe de Operaciones TI | V29: 5.14 Transferencia de información; 8.7 Malware; 8.24 Criptografía; 8.23 Filtrado web | W29: CCN-STIC 804/808, 807
A30: Control de acceso | B30: op.acc.5 | C30: Mecanismo de autenticación (usuarios externos) | D30: ICAT | E30: + [R1 o R2 o R3 o R4] | F30: + [R2 o R3 o R4] + R5 | G30: + [R2 o R3 o R4] + R5 | H30: =IF(OR('Categorización'!F$14="ALTO",'Categorización'!G$14="ALTO",'Categorización'!H$14="ALTO",'Categorización'!I$14="ALTO"),"ALTO",IF(OR('Categorización'!F$14="MEDIO",'Categorización'!G$14="MEDIO",'Categorización'!H$14="MEDIO",'Categorización'!I$14="MEDIO"),"MEDIO","BAJO")) -> ALTO | I30: máx(I=ALTO, C=ALTO, A=ALTO, T=MEDIO) = ALTO | J30: =IF(H30="ALTO",G30,IF(H30="MEDIO",F30,E30)) -> + [R2 o R3 o R4] + R5 | K30: [R2 Contraseña + OTP o R3 Certificados o R4 Certificados en dispositivo físico] R5 Registro | L30: Alternativa elegida: R2 (Cl@ve PIN/permanente) y R3/R4 (certificado/DNIe); + R5 registro. Cumple '[R2 o R3 o R4] + R5'. | M30: SÍ | N30: APLICA: medida vinculada a la(s) dimensión(es) ICAT; nivel exigido ALTO (máx(I=ALTO, C=ALTO, A=ALTO, T=MEDIO) = ALTO). Exigencia: '+ [R2 o R3 o R4] + R5'. Riesgos tratados según AR-2026-01. CCN-STIC 808: 14 requisitos de verificación (10 esenciales). | O30: Usuarios externos (ciudadanos y empleados públicos de las consejerías): política de autenticación NOR-05; registro previo de identidad (R5) mediante Cl@ve / certificado o presencial en oficinas de la consejería; información sobre obligaciones y último acceso. | P30: Integración con Cl@ve (Cl@ve PIN/permanente con OTP = R2; certificado electrónico cualificado = R3; DNIe = R4) para ciudadanos; empleados de las consejerías vía federación SAML con MFA de su organismo; bloqueo tras 5 intentos; sin contraseñas por defecto. | Q30: — | R30: Implantada | S30: 1 | T30: NOR-05; diseño de integración Cl@ve DIS-CLAVE-01; convenio de federación | U30: Responsable del Sistema | V30: 5.17 Información de autenticación; 8.5 Autenticación segura; 5.16 Gestión de identidades | W30: CCN-STIC 804/808, 821
A31: Protección de las comunicaciones | B31: mp.com.4 | C31: Separación de flujos de información en la red | D31: Categoría | E31: n.a. | F31: + [R1 o R2 o R3] | G31: + [R2 o R3] + R4 | H31: =IF('Categorización'!$E$15="ALTA","ALTO",IF('Categorización'!$E$15="MEDIA","MEDIO","BAJO")) -> ALTO | I31: Categoría del sistema = ALTA | J31: =IF(H31="ALTO",G31,IF(H31="MEDIO",F31,E31)) -> + [R2 o R3] + R4 | K31: [R2 Segmentación lógica avanzada o R3 Segmentación física] R4 Puntos de interconexión | L31: Alternativa elegida: R2 (segmentación lógica avanzada) + R4; R3 físico adicional para gestión. Cumple '[R2 o R3] + R4'. | M31: SÍ | N31: APLICA: medida exigida para la categoría ALTA del sistema (afecta a todas las dimensiones). Exigencia: '+ [R2 o R3] + R4'. Riesgos tratados según AR-2026-01. CCN-STIC 808: 6 requisitos de verificación (0 esenciales). | O31: Separación de flujos: segmentación lógica avanzada (R2) por función y nivel (usuarios, administración, servidores por servicio, DMZ, gestión, backup, OT/IoT); control de puntos de interconexión (R4) entre segmentos con cortafuegos y monitorización; segmentación física (R3) para la red de gestión fuera de banda. | P31: VLAN + VRF + microsegmentación (NSX) con políticas por carga; cortafuegos internos entre zonas; red de gestión OOB física; NAC. | Q31: — | R31: Implantada | S31: 1 | T31: ARQ-02 (matriz de zonas y flujos); revisión semestral de políticas de microsegmentación | U31: Jefe de Operaciones TI | V31: 8.22 Segregación de redes; 8.20 Seguridad de redes | W31: CCN-STIC 807, 811, 804/808
A32: Control de acceso | B32: op.acc.6 | C32: Mecanismo de autenticación (usuarios de la organización) | D32: ICAT | E32: + [R1 o R2 o R3 o R4] + R8 + R9 | F32: + [R1 o R2 o R3 o R4] + R5 + R8 + R9 | G32: + [R1 o R2 o R3 o R4] + R5 + R6 + R7 + R8 + R9 | H32: =IF(OR('Categorización'!F$14="ALTO",'Categorización'!G$14="ALTO",'Categorización'!H$14="ALTO",'Categorización'!I$14="ALTO"),"ALTO",IF(OR('Categorización'!F$14="MEDIO",'Categorización'!G$14="MEDIO",'Categorización'!H$14="MEDIO",'Categorización'!I$14="MEDIO"),"MEDIO","BAJO")) -> ALTO | I32: máx(I=ALTO, C=ALTO, A=ALTO, T=MEDIO) = ALTO | J32: =IF(H32="ALTO",G32,IF(H32="MEDIO",F32,E32)) -> + [R1 o R2 o R3 o R4] + R5 + R6 + R7 + R8 + R9 | K32: [R1 Contraseñas o R2 Contraseña + otro factor de autenticación o R3 Certificados o R4 Certificados en dispositivo físico] R5 Registro R6 Limitación de la ventana de acceso R7 Suspensión por no utilización R8 Doble factor para acceso desde o a través de zonas no controladas R9 Acceso remoto (todos los niveles) | L32: Alternativa elegida: R2 para todo el personal y R4 para administradores. Cumple '[R1 o R2 o R3 o R4] + R5 + R6 + R7 + R8 + R9'. | M32: SÍ | N32: APLICA: medida vinculada a la(s) dimensión(es) ICAT; nivel exigido ALTO (máx(I=ALTO, C=ALTO, A=ALTO, T=MEDIO) = ALTO). Exigencia: '+ [R1 o R2 o R3 o R4] + R5 + R6 + R7 + R8 + R9'. Riesgos tratados según AR-2026-01. CCN-STIC 808: 14 requisitos de verificación (7 esenciales). | O32: Usuarios de TechServ: NOR-05 (contraseñas ≥14 caracteres, no reutilización, cambio ante sospecha); registro previo (R5) por RRHH; ventana de acceso limitada por horario y rol para administradores (R6); suspensión a los 45 días sin uso (R7); acceso remoto sólo por VPN con MFA (R8/R9). | P32: MFA obligatorio para todos (R2: contraseña + token FIDO2/app); administradores con certificado en tarjeta criptográfica (R4); AD con políticas de contraseñas y bloqueo; PAM; VPN con MFA y posture check; políticas de horario en AD/PAM; script de suspensión por inactividad. | Q32: — | R32: Implantada | S32: 1 | T32: NOR-05; GPO-AUTH-01; informe PAM; REG-IAM-SUSP | U32: Responsable del Sistema | V32: 8.5 Autenticación segura; 5.17 Información de autenticación; 6.7 Trabajo remoto; 8.1 Dispositivos de usuario | W32: CCN-STIC 804/808, 821
A33: Recursos externos | B33: op.ext.3 | C33: Protección de la cadena de suministro | D33: Categoría | E33: n.a. | F33: n.a. | G33: aplica | H33: =IF('Categorización'!$E$15="ALTA","ALTO",IF('Categorización'!$E$15="MEDIA","MEDIO","BAJO")) -> ALTO | I33: Categoría del sistema = ALTA | J33: =IF(H33="ALTO",G33,IF(H33="MEDIO",F33,E33)) -> aplica | K33: — | L33: Aplica sólo en categoría ALTA → aplica. | M33: SÍ | N33: APLICA: medida exigida para la categoría ALTA del sistema (afecta a todas las dimensiones). Exigencia: 'aplica'. Riesgos tratados según AR-2026-01. CCN-STIC 808: 5 requisitos de verificación (0 esenciales). | O33: Protección de la cadena de suministro: due diligence de seguridad antes de contratar (cuestionario CCN-STIC 830 / ISO 27036), verificación de certificaciones (ENS, 27001), plan de contingencia por proveedor crítico, exigencia de SBOM a desarrolladores externos, revisión anual de riesgos de la cadena. | P33: Análisis de composición de software (SCA) en el pipeline; monitorización de exposición de proveedores (rating externo). | Q33: — | R33: Implantada | S33: 1 | T33: Evaluaciones de proveedores 2026; plan de contingencia PROV-CONT-01; informes SCA | U33: Responsable de Seguridad | V33: 5.21 Seguridad en la cadena de suministro TIC; 5.29 Seguridad durante la disrupción; 5.30 Preparación de las TIC para la continuidad | W33: CCN-STIC 811, 830, 804/808
A34: Protección de los equipos | B34: mp.eq.2 | C34: Bloqueo de puesto de trabajo | D34: A | E34: n.a. | F34: aplica | G34: + R1 | H34: =IF(OR('Categorización'!H$14="ALTO"),"ALTO",IF(OR('Categorización'!H$14="MEDIO"),"MEDIO","BAJO")) -> ALTO | I34: máx(A=ALTO) = ALTO | J34: =IF(H34="ALTO",G34,IF(H34="MEDIO",F34,E34)) -> + R1 | K34: R1 Cierre de sesiones | L34: Dimensión A = ALTO → R1 exigido → cumplido. | M34: SÍ | N34: APLICA: medida vinculada a la(s) dimensión(es) A; nivel exigido ALTO (máx(A=ALTO) = ALTO). Exigencia: '+ R1'. Riesgos tratados según AR-2026-01. CCN-STIC 808: 1 requisitos de verificación (1 esenciales). | O34: Bloqueo de sesión por inactividad y cierre de sesiones (R1) al final de la jornada o tras inactividad prolongada; obligación de bloquear al ausentarse. | P34: GPO: bloqueo a 5 min (puestos) y 2 min (consolas de administración); cierre de sesión forzado a las 8 h; PAM cierra sesiones privilegiadas inactivas a los 10 min. | Q34: — | R34: Implantada | S34: 1 | T34: GPO-LOCK-01; informes de cumplimiento | U34: Jefe de Operaciones TI | V34: 7.7 Escritorio y pantalla despejados; 8.1 Dispositivos de usuario | W34: CCN-STIC 804/808, 5xx
A35: Protección de los soportes de información | B35: mp.si.1 | C35: Marcado de soportes | D35: C | E35: n.a. | F35: aplica | G35: aplica | H35: =IF(OR('Categorización'!G$14="ALTO"),"ALTO",IF(OR('Categorización'!G$14="MEDIO"),"MEDIO","BAJO")) -> ALTO | I35: máx(C=ALTO) = ALTO | J35: =IF(H35="ALTO",G35,IF(H35="MEDIO",F35,E35)) -> aplica | K35: — | L35: Dimensión C = ALTO → aplica. | M35: SÍ | N35: APLICA: medida vinculada a la(s) dimensión(es) C; nivel exigido ALTO (máx(C=ALTO) = ALTO). Exigencia: 'aplica'. Riesgos tratados según AR-2026-01. CCN-STIC 808: 6 requisitos de verificación (0 esenciales). | O35: Marcado de soportes según el nivel de calificación de la información (NOR-04): etiqueta con nivel, propietario e identificador; los usuarios conocen el significado de las etiquetas. | P35: Etiquetas físicas normalizadas; etiquetado lógico (metadatos) en cintas y discos extraíbles; inventario en CMDB. | Q35: — | R35: Implantada | S35: 1 | T35: NOR-04; inventario de soportes INV-SOP | U35: Jefe de Operaciones TI | V35: 5.13 Etiquetado de la información; 7.10 Soportes de almacenamiento | W35: CCN-STIC 807, 804/808
A36: Protección de la información | B36: mp.info.2 | C36: Calificación de la información | D36: C | E36: n.a. | F36: aplica | G36: aplica | H36: =IF(OR('Categorización'!G$14="ALTO"),"ALTO",IF(OR('Categorización'!G$14="MEDIO"),"MEDIO","BAJO")) -> ALTO | I36: máx(C=ALTO) = ALTO | J36: =IF(H36="ALTO",G36,IF(H36="MEDIO",F36,E36)) -> aplica | K36: — | L36: Dimensión C = ALTO → aplica. | M36: SÍ | N36: APLICA: medida vinculada a la(s) dimensión(es) C; nivel exigido ALTO (máx(C=ALTO) = ALTO). Exigencia: 'aplica'. Riesgos tratados según AR-2026-01. CCN-STIC 808: 7 requisitos de verificación (2 esenciales). | O36: Política de calificación de la información NOR-04: niveles (PÚBLICO, USO INTERNO, CONFIDENCIAL, RESERVADO) alineados con el nivel de C del Anexo I; el Responsable de la Información califica; procedimientos de manejo por nivel (etiquetado, acceso, cifrado, transmisión, destrucción). | P36: Etiquetado de documentos (MIP/AIP) con DLP asociado; clasificación en repositorios. | Q36: — | R36: Implantada | S36: 1 | T36: NOR-04; guía de manejo por nivel; informes DLP | U36: Responsable de Seguridad | V36: 5.12 Clasificación de la información; 5.13 Etiquetado | W36: CCN-STIC 807, 804/808
A37: Protección de la información | B37: mp.info.5 | C37: Limpieza de documentos | D37: C | E37: aplica | F37: aplica | G37: aplica | H37: =IF(OR('Categorización'!G$14="ALTO"),"ALTO",IF(OR('Categorización'!G$14="MEDIO"),"MEDIO","BAJO")) -> ALTO | I37: máx(C=ALTO) = ALTO | J37: =IF(H37="ALTO",G37,IF(H37="MEDIO",F37,E37)) -> aplica | K37: — | L37: Dimensión C = ALTO → aplica. | M37: SÍ | N37: APLICA: medida vinculada a la(s) dimensión(es) C; nivel exigido ALTO (máx(C=ALTO) = ALTO). Exigencia: 'aplica'. Riesgos tratados según AR-2026-01. CCN-STIC 808: 2 requisitos de verificación (1 esenciales). | O37: Limpieza de documentos: procedimiento de retirada de metadatos, comentarios, cambios y campos ocultos antes de publicar o transferir documentos fuera del nivel de calificación; formación a usuarios. | P37: Limpieza automática de metadatos en la pasarela de correo y en el portal de publicación (herramienta OlvidoMeta / DLP); plantillas corporativas sin campos ocultos. | Q37: — | R37: Implantada | S37: 1 | T37: PRO-INFO-02; configuración DLP | U37: Responsable de Seguridad | V37: 5.14 Transferencia de información; 8.10 Borrado de información (sin equivalente directo) | W37: CCN-STIC 807, 804/808
